[2024-11-21 12:13:36,437] {taskinstance.py:896} INFO - Dependencies all met for <TaskInstance: kpi_calculation_pipeline.calculate_kpi 2024-11-21T12:07:13.983902+00:00 [queued]>
[2024-11-21 12:13:36,562] {taskinstance.py:896} INFO - Dependencies all met for <TaskInstance: kpi_calculation_pipeline.calculate_kpi 2024-11-21T12:07:13.983902+00:00 [queued]>
[2024-11-21 12:13:36,596] {taskinstance.py:1087} INFO - 
--------------------------------------------------------------------------------
[2024-11-21 12:13:36,597] {taskinstance.py:1088} INFO - Starting attempt 2 of 2
[2024-11-21 12:13:36,598] {taskinstance.py:1089} INFO - 
--------------------------------------------------------------------------------
[2024-11-21 12:13:36,975] {taskinstance.py:1107} INFO - Executing <Task(PythonOperator): calculate_kpi> on 2024-11-21T12:07:13.983902+00:00
[2024-11-21 12:13:36,982] {standard_task_runner.py:52} INFO - Started process 2997 to run task
[2024-11-21 12:13:36,988] {standard_task_runner.py:76} INFO - Running: ['airflow', 'tasks', 'run', 'kpi_calculation_pipeline', 'calculate_kpi', '2024-11-21T12:07:13.983902+00:00', '--job-id', '121', '--pool', 'default_pool', '--raw', '--subdir', 'DAGS_FOLDER/data_injestion_dag/bazefield_kpi_calculation.py', '--cfg-path', '/tmp/tmpalmdnm2k', '--error-file', '/tmp/tmplo5vuvgq']
[2024-11-21 12:13:36,989] {standard_task_runner.py:77} INFO - Job 121: Subtask calculate_kpi
[2024-11-21 12:13:37,491] {logging_mixin.py:104} INFO - Running <TaskInstance: kpi_calculation_pipeline.calculate_kpi 2024-11-21T12:07:13.983902+00:00 [running]> on host 1b505405454d
[2024-11-21 12:13:38,266] {taskinstance.py:1300} INFO - Exporting the following env vars:
AIRFLOW_CTX_DAG_OWNER=airflow
AIRFLOW_CTX_DAG_ID=kpi_calculation_pipeline
AIRFLOW_CTX_TASK_ID=calculate_kpi
AIRFLOW_CTX_EXECUTION_DATE=2024-11-21T12:07:13.983902+00:00
AIRFLOW_CTX_DAG_RUN_ID=scheduled__2024-11-21T12:07:13.983902+00:00
[2024-11-21 12:13:38,321] {taskinstance.py:1501} ERROR - Task failed with exception
Traceback (most recent call last):
  File "/home/airflow/.local/lib/python3.8/site-packages/airflow/models/taskinstance.py", line 1157, in _run_raw_task
    self._prepare_and_execute_task_with_callbacks(context, task)
  File "/home/airflow/.local/lib/python3.8/site-packages/airflow/models/taskinstance.py", line 1331, in _prepare_and_execute_task_with_callbacks
    result = self._execute_task(context, task_copy)
  File "/home/airflow/.local/lib/python3.8/site-packages/airflow/models/taskinstance.py", line 1361, in _execute_task
    result = task_copy.execute(context=context)
  File "/home/airflow/.local/lib/python3.8/site-packages/airflow/operators/python.py", line 150, in execute
    return_value = self.execute_callable()
  File "/home/airflow/.local/lib/python3.8/site-packages/airflow/operators/python.py", line 161, in execute_callable
    return self.python_callable(*self.op_args, **self.op_kwargs)
  File "/opt/airflow/dags/data_injestion_dag/bazefield_kpi_calculation.py", line 301, in calculate_kpi
    raise ValueError("No data received from API")
ValueError: No data received from API
[2024-11-21 12:13:38,345] {taskinstance.py:1544} INFO - Marking task as FAILED. dag_id=kpi_calculation_pipeline, task_id=calculate_kpi, execution_date=20241121T120713, start_date=20241121T121336, end_date=20241121T121338
[2024-11-21 12:13:38,677] {local_task_job.py:151} INFO - Task exited with return code 1
