[2024-11-21 10:28:06,639] {taskinstance.py:896} INFO - Dependencies all met for <TaskInstance: kpi_calculation_pipeline.fetch_data 2024-11-21T10:27:58.802048+00:00 [queued]>
[2024-11-21 10:28:06,869] {taskinstance.py:896} INFO - Dependencies all met for <TaskInstance: kpi_calculation_pipeline.fetch_data 2024-11-21T10:27:58.802048+00:00 [queued]>
[2024-11-21 10:28:06,870] {taskinstance.py:1087} INFO - 
--------------------------------------------------------------------------------
[2024-11-21 10:28:06,871] {taskinstance.py:1088} INFO - Starting attempt 1 of 2
[2024-11-21 10:28:06,872] {taskinstance.py:1089} INFO - 
--------------------------------------------------------------------------------
[2024-11-21 10:28:07,421] {taskinstance.py:1107} INFO - Executing <Task(PythonOperator): fetch_data> on 2024-11-21T10:27:58.802048+00:00
[2024-11-21 10:28:07,426] {standard_task_runner.py:52} INFO - Started process 610 to run task
[2024-11-21 10:28:07,429] {standard_task_runner.py:76} INFO - Running: ['airflow', 'tasks', 'run', 'kpi_calculation_pipeline', 'fetch_data', '2024-11-21T10:27:58.802048+00:00', '--job-id', '28', '--pool', 'default_pool', '--raw', '--subdir', 'DAGS_FOLDER/data_injestion_dag/bazefield_kpi_calculation.py', '--cfg-path', '/tmp/tmpr7dbo1yr', '--error-file', '/tmp/tmp73cz_9sd']
[2024-11-21 10:28:07,431] {standard_task_runner.py:77} INFO - Job 28: Subtask fetch_data
[2024-11-21 10:28:07,912] {logging_mixin.py:104} INFO - Running <TaskInstance: kpi_calculation_pipeline.fetch_data 2024-11-21T10:27:58.802048+00:00 [running]> on host bf5936288309
[2024-11-21 10:28:08,713] {taskinstance.py:1300} INFO - Exporting the following env vars:
AIRFLOW_CTX_DAG_OWNER=airflow
AIRFLOW_CTX_DAG_ID=kpi_calculation_pipeline
AIRFLOW_CTX_TASK_ID=fetch_data
AIRFLOW_CTX_EXECUTION_DATE=2024-11-21T10:27:58.802048+00:00
AIRFLOW_CTX_DAG_RUN_ID=manual__2024-11-21T10:27:58.802048+00:00
[2024-11-21 10:28:08,715] {taskinstance.py:1501} ERROR - Task failed with exception
Traceback (most recent call last):
  File "/home/airflow/.local/lib/python3.8/site-packages/airflow/models/taskinstance.py", line 1157, in _run_raw_task
    self._prepare_and_execute_task_with_callbacks(context, task)
  File "/home/airflow/.local/lib/python3.8/site-packages/airflow/models/taskinstance.py", line 1331, in _prepare_and_execute_task_with_callbacks
    result = self._execute_task(context, task_copy)
  File "/home/airflow/.local/lib/python3.8/site-packages/airflow/models/taskinstance.py", line 1361, in _execute_task
    result = task_copy.execute(context=context)
  File "/home/airflow/.local/lib/python3.8/site-packages/airflow/operators/python.py", line 150, in execute
    return_value = self.execute_callable()
  File "/home/airflow/.local/lib/python3.8/site-packages/airflow/operators/python.py", line 161, in execute_callable
    return self.python_callable(*self.op_args, **self.op_kwargs)
  File "/opt/airflow/dags/data_injestion_dag/bazefield_kpi_calculation.py", line 37, in fetch_active_power_kpi
    object_ids = extras.get('object_ids', [])
NameError: name 'extras' is not defined
[2024-11-21 10:28:08,724] {taskinstance.py:1544} INFO - Marking task as UP_FOR_RETRY. dag_id=kpi_calculation_pipeline, task_id=fetch_data, execution_date=20241121T102758, start_date=20241121T102806, end_date=20241121T102808
[2024-11-21 10:28:09,269] {local_task_job.py:151} INFO - Task exited with return code 1
