[2024-11-22 05:36:12,452] {taskinstance.py:896} INFO - Dependencies all met for <TaskInstance: kpi_calculation_pipeline.store_kpi 2024-11-22T05:35:59.958266+00:00 [queued]>
[2024-11-22 05:36:12,516] {taskinstance.py:896} INFO - Dependencies all met for <TaskInstance: kpi_calculation_pipeline.store_kpi 2024-11-22T05:35:59.958266+00:00 [queued]>
[2024-11-22 05:36:12,517] {taskinstance.py:1087} INFO - 
--------------------------------------------------------------------------------
[2024-11-22 05:36:12,517] {taskinstance.py:1088} INFO - Starting attempt 1 of 2
[2024-11-22 05:36:12,518] {taskinstance.py:1089} INFO - 
--------------------------------------------------------------------------------
[2024-11-22 05:36:12,608] {taskinstance.py:1107} INFO - Executing <Task(PythonOperator): store_kpi> on 2024-11-22T05:35:59.958266+00:00
[2024-11-22 05:36:12,613] {standard_task_runner.py:52} INFO - Started process 1746 to run task
[2024-11-22 05:36:12,616] {standard_task_runner.py:76} INFO - Running: ['airflow', 'tasks', 'run', 'kpi_calculation_pipeline', 'store_kpi', '2024-11-22T05:35:59.958266+00:00', '--job-id', '273', '--pool', 'default_pool', '--raw', '--subdir', 'DAGS_FOLDER/data_injestion_dag/bazefield_kpi_calculation.py', '--cfg-path', '/tmp/tmp6buus1si', '--error-file', '/tmp/tmpc3gkgnjo']
[2024-11-22 05:36:12,617] {standard_task_runner.py:77} INFO - Job 273: Subtask store_kpi
[2024-11-22 05:36:12,759] {logging_mixin.py:104} INFO - Running <TaskInstance: kpi_calculation_pipeline.store_kpi 2024-11-22T05:35:59.958266+00:00 [running]> on host 1b505405454d
[2024-11-22 05:36:12,970] {taskinstance.py:1300} INFO - Exporting the following env vars:
AIRFLOW_CTX_DAG_OWNER=airflow
AIRFLOW_CTX_DAG_ID=kpi_calculation_pipeline
AIRFLOW_CTX_TASK_ID=store_kpi
AIRFLOW_CTX_EXECUTION_DATE=2024-11-22T05:35:59.958266+00:00
AIRFLOW_CTX_DAG_RUN_ID=manual__2024-11-22T05:35:59.958266+00:00
[2024-11-22 05:36:12,995] {taskinstance.py:1501} ERROR - Task failed with exception
Traceback (most recent call last):
  File "/home/airflow/.local/lib/python3.8/site-packages/airflow/models/taskinstance.py", line 1157, in _run_raw_task
    self._prepare_and_execute_task_with_callbacks(context, task)
  File "/home/airflow/.local/lib/python3.8/site-packages/airflow/models/taskinstance.py", line 1331, in _prepare_and_execute_task_with_callbacks
    result = self._execute_task(context, task_copy)
  File "/home/airflow/.local/lib/python3.8/site-packages/airflow/models/taskinstance.py", line 1361, in _execute_task
    result = task_copy.execute(context=context)
  File "/home/airflow/.local/lib/python3.8/site-packages/airflow/operators/python.py", line 150, in execute
    return_value = self.execute_callable()
  File "/home/airflow/.local/lib/python3.8/site-packages/airflow/operators/python.py", line 161, in execute_callable
    return self.python_callable(*self.op_args, **self.op_kwargs)
  File "/opt/airflow/dags/data_injestion_dag/bazefield_kpi_calculation.py", line 324, in store_kpi_in_postgres
    postgres_hook = PostgresHook(postgres_conn_id='kpi_conn')
NameError: name 'PostgresHook' is not defined
[2024-11-22 05:36:13,002] {taskinstance.py:1544} INFO - Marking task as UP_FOR_RETRY. dag_id=kpi_calculation_pipeline, task_id=store_kpi, execution_date=20241122T053559, start_date=20241122T053612, end_date=20241122T053613
[2024-11-22 05:36:13,125] {local_task_job.py:151} INFO - Task exited with return code 1
