[2024-11-22 05:58:57,741] {taskinstance.py:896} INFO - Dependencies all met for <TaskInstance: kpi_calculation_pipeline.fetch_data 2024-11-22T05:52:44.998804+00:00 [queued]>
[2024-11-22 05:58:57,776] {taskinstance.py:896} INFO - Dependencies all met for <TaskInstance: kpi_calculation_pipeline.fetch_data 2024-11-22T05:52:44.998804+00:00 [queued]>
[2024-11-22 05:58:57,776] {taskinstance.py:1087} INFO - 
--------------------------------------------------------------------------------
[2024-11-22 05:58:57,777] {taskinstance.py:1088} INFO - Starting attempt 2 of 2
[2024-11-22 05:58:57,777] {taskinstance.py:1089} INFO - 
--------------------------------------------------------------------------------
[2024-11-22 05:58:57,816] {taskinstance.py:1107} INFO - Executing <Task(PythonOperator): fetch_data> on 2024-11-22T05:52:44.998804+00:00
[2024-11-22 05:58:57,819] {standard_task_runner.py:52} INFO - Started process 2834 to run task
[2024-11-22 05:58:57,822] {standard_task_runner.py:76} INFO - Running: ['airflow', 'tasks', 'run', 'kpi_calculation_pipeline', 'fetch_data', '2024-11-22T05:52:44.998804+00:00', '--job-id', '309', '--pool', 'default_pool', '--raw', '--subdir', 'DAGS_FOLDER/data_injestion_dag/bazefield_kpi_calculation.py', '--cfg-path', '/tmp/tmpp0ncak15', '--error-file', '/tmp/tmpt2df5i4d']
[2024-11-22 05:58:57,823] {standard_task_runner.py:77} INFO - Job 309: Subtask fetch_data
[2024-11-22 05:58:57,893] {logging_mixin.py:104} INFO - Running <TaskInstance: kpi_calculation_pipeline.fetch_data 2024-11-22T05:52:44.998804+00:00 [running]> on host 1b505405454d
[2024-11-22 05:58:57,999] {taskinstance.py:1300} INFO - Exporting the following env vars:
AIRFLOW_CTX_DAG_OWNER=airflow
AIRFLOW_CTX_DAG_ID=kpi_calculation_pipeline
AIRFLOW_CTX_TASK_ID=fetch_data
AIRFLOW_CTX_EXECUTION_DATE=2024-11-22T05:52:44.998804+00:00
AIRFLOW_CTX_DAG_RUN_ID=scheduled__2024-11-22T05:52:44.998804+00:00
[2024-11-22 05:58:58,000] {logging_mixin.py:104} INFO - fetching api data between 2024-11-22T04:00:00Z and 2024-11-22T04:59:59Z
[2024-11-22 05:58:58,013] {base.py:69} INFO - Using connection to: id: bazefield_api. Host: https://idcc.jsw.in, Port: None, Schema: , Login: , Password: None, extra: {'Authorization': '***'}
[2024-11-22 05:58:58,015] {http.py:140} INFO - Sending 'GET' to url: https://idcc.jsw.in/Bazefield.Services/api/objects/timeseries/aggregated?objectIds=11002CC087CEB000,11003170EE0EB000,11003170FD4EB000,110031710ACEB000,110031717B8EB000,11003171B24EB000,11003171C00EB000,11003171DD8EB000,11003171EB8EB000,110031733E0EB000,110031734C4EB000,110031735B4EB000,11003176A54EB000,11003177284EB000,1100317739CEB000,110031720D0EB000,11003173790EB000,11003173A68EB000,110031758CCEB000,11003176424EB000,11003176520EB000,11003176620EB000,11003176834EB000,11003173004EB000,110031730FCEB000,11003175A08EB000,11003175C24EB000,11003175D24EB000,11003175E94EB000,11003175FB4EB000,11003176324EB000,110031775B8EB000,11003171260EB000,11003171344EB000,11003171438EB000,11003171520EB000,11003171608EB000,110031716F0EB000,1100317188CEB000,11003171960EB000,11003171A48EB000,11003171CF0EB000,11003171FF0EB000,1100317369CEB000,110031723ACEB000,11003172488EB000,1100317257CEB000,11003172664EB000,11003172750EB000,1100317283CEB000,11003172928EB000,11003175B1CEB000,11003176724EB000,11003176938EB000,110031774A8EB000,110031721D0EB000,110031722CCEB000,11003172A20EB000,11003172B08EB000,11003172BFCEB000,11003173894EB000,11003173988EB000,1100317621CEB000,11003176C94EB000,11003176DCCEB000,11003177174EB000,11003172CE4EB000,11003172DD8EB000,11003172F0CEB000,11003173B58EB000,11003173C54EB000,11003173D50EB000,11003174760EB000,11003175698EB000,11003176B68EB000,11003176F14EB000,1100317705CEB000,11003174B6CEB000,11003175278EB000,11003175374EB000,110031755A0EB000,11003173F2CEB000,11003174C68EB000,11003174D68EB000,11003174F64EB000,11003175060EB000,11003175178EB000,11003175480EB000,110031760C4EB000,11003173E34EB000,11003174030EB000,11003174660EB000,1100317487CEB000,11003174978EB000,11003174A7CEB000,110031731F0EB000,110031732F0EB000,1100317411CEB000,11003174214EB000,11003174324EB000,1100317443CEB000,11003174544EB000,11003174E6CEB000,110031757B4EB000&points=ActivePower&aggregates=TIMEAVERAGE&from=2024-11-22T04:00:00Z&to=2024-11-22T04:59:59Z&interval=10m&format=json
[2024-11-22 05:59:23,058] {http.py:202} WARNING - HTTPSConnectionPool(host='idcc.jsw.in', port=443): Max retries exceeded with url: /Bazefield.Services/api/objects/timeseries/aggregated?objectIds=11002CC087CEB000,11003170EE0EB000,11003170FD4EB000,110031710ACEB000,110031717B8EB000,11003171B24EB000,11003171C00EB000,11003171DD8EB000,11003171EB8EB000,110031733E0EB000,110031734C4EB000,110031735B4EB000,11003176A54EB000,11003177284EB000,1100317739CEB000,110031720D0EB000,11003173790EB000,11003173A68EB000,110031758CCEB000,11003176424EB000,11003176520EB000,11003176620EB000,11003176834EB000,11003173004EB000,110031730FCEB000,11003175A08EB000,11003175C24EB000,11003175D24EB000,11003175E94EB000,11003175FB4EB000,11003176324EB000,110031775B8EB000,11003171260EB000,11003171344EB000,11003171438EB000,11003171520EB000,11003171608EB000,110031716F0EB000,1100317188CEB000,11003171960EB000,11003171A48EB000,11003171CF0EB000,11003171FF0EB000,1100317369CEB000,110031723ACEB000,11003172488EB000,1100317257CEB000,11003172664EB000,11003172750EB000,1100317283CEB000,11003172928EB000,11003175B1CEB000,11003176724EB000,11003176938EB000,110031774A8EB000,110031721D0EB000,110031722CCEB000,11003172A20EB000,11003172B08EB000,11003172BFCEB000,11003173894EB000,11003173988EB000,1100317621CEB000,11003176C94EB000,11003176DCCEB000,11003177174EB000,11003172CE4EB000,11003172DD8EB000,11003172F0CEB000,11003173B58EB000,11003173C54EB000,11003173D50EB000,11003174760EB000,11003175698EB000,11003176B68EB000,11003176F14EB000,1100317705CEB000,11003174B6CEB000,11003175278EB000,11003175374EB000,110031755A0EB000,11003173F2CEB000,11003174C68EB000,11003174D68EB000,11003174F64EB000,11003175060EB000,11003175178EB000,11003175480EB000,110031760C4EB000,11003173E34EB000,11003174030EB000,11003174660EB000,1100317487CEB000,11003174978EB000,11003174A7CEB000,110031731F0EB000,110031732F0EB000,1100317411CEB000,11003174214EB000,11003174324EB000,1100317443CEB000,11003174544EB000,11003174E6CEB000,110031757B4EB000&points=ActivePower&aggregates=TIMEAVERAGE&from=2024-11-22T04:00:00Z&to=2024-11-22T04:59:59Z&interval=10m&format=json (Caused by NewConnectionError('<urllib3.connection.HTTPSConnection object at 0x7fd7c44aeb80>: Failed to establish a new connection: [Errno 111] Connection refused')) Tenacity will retry to execute the operation
[2024-11-22 05:59:23,059] {taskinstance.py:1501} ERROR - Task failed with exception
Traceback (most recent call last):
  File "/home/airflow/.local/lib/python3.8/site-packages/urllib3/connection.py", line 159, in _new_conn
    conn = connection.create_connection(
  File "/home/airflow/.local/lib/python3.8/site-packages/urllib3/util/connection.py", line 84, in create_connection
    raise err
  File "/home/airflow/.local/lib/python3.8/site-packages/urllib3/util/connection.py", line 74, in create_connection
    sock.connect(sa)
ConnectionRefusedError: [Errno 111] Connection refused

During handling of the above exception, another exception occurred:

Traceback (most recent call last):
  File "/home/airflow/.local/lib/python3.8/site-packages/urllib3/connectionpool.py", line 670, in urlopen
    httplib_response = self._make_request(
  File "/home/airflow/.local/lib/python3.8/site-packages/urllib3/connectionpool.py", line 381, in _make_request
    self._validate_conn(conn)
  File "/home/airflow/.local/lib/python3.8/site-packages/urllib3/connectionpool.py", line 978, in _validate_conn
    conn.connect()
  File "/home/airflow/.local/lib/python3.8/site-packages/urllib3/connection.py", line 309, in connect
    conn = self._new_conn()
  File "/home/airflow/.local/lib/python3.8/site-packages/urllib3/connection.py", line 171, in _new_conn
    raise NewConnectionError(
urllib3.exceptions.NewConnectionError: <urllib3.connection.HTTPSConnection object at 0x7fd7c44aeb80>: Failed to establish a new connection: [Errno 111] Connection refused

During handling of the above exception, another exception occurred:

Traceback (most recent call last):
  File "/home/airflow/.local/lib/python3.8/site-packages/requests/adapters.py", line 439, in send
    resp = conn.urlopen(
  File "/home/airflow/.local/lib/python3.8/site-packages/urllib3/connectionpool.py", line 726, in urlopen
    retries = retries.increment(
  File "/home/airflow/.local/lib/python3.8/site-packages/urllib3/util/retry.py", line 446, in increment
    raise MaxRetryError(_pool, url, error or ResponseError(cause))
urllib3.exceptions.MaxRetryError: HTTPSConnectionPool(host='idcc.jsw.in', port=443): Max retries exceeded with url: /Bazefield.Services/api/objects/timeseries/aggregated?objectIds=11002CC087CEB000,11003170EE0EB000,11003170FD4EB000,110031710ACEB000,110031717B8EB000,11003171B24EB000,11003171C00EB000,11003171DD8EB000,11003171EB8EB000,110031733E0EB000,110031734C4EB000,110031735B4EB000,11003176A54EB000,11003177284EB000,1100317739CEB000,110031720D0EB000,11003173790EB000,11003173A68EB000,110031758CCEB000,11003176424EB000,11003176520EB000,11003176620EB000,11003176834EB000,11003173004EB000,110031730FCEB000,11003175A08EB000,11003175C24EB000,11003175D24EB000,11003175E94EB000,11003175FB4EB000,11003176324EB000,110031775B8EB000,11003171260EB000,11003171344EB000,11003171438EB000,11003171520EB000,11003171608EB000,110031716F0EB000,1100317188CEB000,11003171960EB000,11003171A48EB000,11003171CF0EB000,11003171FF0EB000,1100317369CEB000,110031723ACEB000,11003172488EB000,1100317257CEB000,11003172664EB000,11003172750EB000,1100317283CEB000,11003172928EB000,11003175B1CEB000,11003176724EB000,11003176938EB000,110031774A8EB000,110031721D0EB000,110031722CCEB000,11003172A20EB000,11003172B08EB000,11003172BFCEB000,11003173894EB000,11003173988EB000,1100317621CEB000,11003176C94EB000,11003176DCCEB000,11003177174EB000,11003172CE4EB000,11003172DD8EB000,11003172F0CEB000,11003173B58EB000,11003173C54EB000,11003173D50EB000,11003174760EB000,11003175698EB000,11003176B68EB000,11003176F14EB000,1100317705CEB000,11003174B6CEB000,11003175278EB000,11003175374EB000,110031755A0EB000,11003173F2CEB000,11003174C68EB000,11003174D68EB000,11003174F64EB000,11003175060EB000,11003175178EB000,11003175480EB000,110031760C4EB000,11003173E34EB000,11003174030EB000,11003174660EB000,1100317487CEB000,11003174978EB000,11003174A7CEB000,110031731F0EB000,110031732F0EB000,1100317411CEB000,11003174214EB000,11003174324EB000,1100317443CEB000,11003174544EB000,11003174E6CEB000,110031757B4EB000&points=ActivePower&aggregates=TIMEAVERAGE&from=2024-11-22T04:00:00Z&to=2024-11-22T04:59:59Z&interval=10m&format=json (Caused by NewConnectionError('<urllib3.connection.HTTPSConnection object at 0x7fd7c44aeb80>: Failed to establish a new connection: [Errno 111] Connection refused'))

During handling of the above exception, another exception occurred:

Traceback (most recent call last):
  File "/opt/airflow/dags/data_injestion_dag/bazefield_kpi_calculation.py", line 266, in fetch_active_power_kpi
    response = http_hook.run(endpoint=full_endpoint)
  File "/home/airflow/.local/lib/python3.8/site-packages/airflow/providers/http/hooks/http.py", line 141, in run
    return self.run_and_check(session, prepped_request, extra_options)
  File "/home/airflow/.local/lib/python3.8/site-packages/airflow/providers/http/hooks/http.py", line 203, in run_and_check
    raise ex
  File "/home/airflow/.local/lib/python3.8/site-packages/airflow/providers/http/hooks/http.py", line 195, in run_and_check
    response = session.send(prepped_request, **send_kwargs)
  File "/home/airflow/.local/lib/python3.8/site-packages/requests/sessions.py", line 655, in send
    r = adapter.send(request, **kwargs)
  File "/home/airflow/.local/lib/python3.8/site-packages/requests/adapters.py", line 516, in send
    raise ConnectionError(e, request=request)
requests.exceptions.ConnectionError: HTTPSConnectionPool(host='idcc.jsw.in', port=443): Max retries exceeded with url: /Bazefield.Services/api/objects/timeseries/aggregated?objectIds=11002CC087CEB000,11003170EE0EB000,11003170FD4EB000,110031710ACEB000,110031717B8EB000,11003171B24EB000,11003171C00EB000,11003171DD8EB000,11003171EB8EB000,110031733E0EB000,110031734C4EB000,110031735B4EB000,11003176A54EB000,11003177284EB000,1100317739CEB000,110031720D0EB000,11003173790EB000,11003173A68EB000,110031758CCEB000,11003176424EB000,11003176520EB000,11003176620EB000,11003176834EB000,11003173004EB000,110031730FCEB000,11003175A08EB000,11003175C24EB000,11003175D24EB000,11003175E94EB000,11003175FB4EB000,11003176324EB000,110031775B8EB000,11003171260EB000,11003171344EB000,11003171438EB000,11003171520EB000,11003171608EB000,110031716F0EB000,1100317188CEB000,11003171960EB000,11003171A48EB000,11003171CF0EB000,11003171FF0EB000,1100317369CEB000,110031723ACEB000,11003172488EB000,1100317257CEB000,11003172664EB000,11003172750EB000,1100317283CEB000,11003172928EB000,11003175B1CEB000,11003176724EB000,11003176938EB000,110031774A8EB000,110031721D0EB000,110031722CCEB000,11003172A20EB000,11003172B08EB000,11003172BFCEB000,11003173894EB000,11003173988EB000,1100317621CEB000,11003176C94EB000,11003176DCCEB000,11003177174EB000,11003172CE4EB000,11003172DD8EB000,11003172F0CEB000,11003173B58EB000,11003173C54EB000,11003173D50EB000,11003174760EB000,11003175698EB000,11003176B68EB000,11003176F14EB000,1100317705CEB000,11003174B6CEB000,11003175278EB000,11003175374EB000,110031755A0EB000,11003173F2CEB000,11003174C68EB000,11003174D68EB000,11003174F64EB000,11003175060EB000,11003175178EB000,11003175480EB000,110031760C4EB000,11003173E34EB000,11003174030EB000,11003174660EB000,1100317487CEB000,11003174978EB000,11003174A7CEB000,110031731F0EB000,110031732F0EB000,1100317411CEB000,11003174214EB000,11003174324EB000,1100317443CEB000,11003174544EB000,11003174E6CEB000,110031757B4EB000&points=ActivePower&aggregates=TIMEAVERAGE&from=2024-11-22T04:00:00Z&to=2024-11-22T04:59:59Z&interval=10m&format=json (Caused by NewConnectionError('<urllib3.connection.HTTPSConnection object at 0x7fd7c44aeb80>: Failed to establish a new connection: [Errno 111] Connection refused'))

During handling of the above exception, another exception occurred:

Traceback (most recent call last):
  File "/home/airflow/.local/lib/python3.8/site-packages/airflow/models/taskinstance.py", line 1157, in _run_raw_task
    self._prepare_and_execute_task_with_callbacks(context, task)
  File "/home/airflow/.local/lib/python3.8/site-packages/airflow/models/taskinstance.py", line 1331, in _prepare_and_execute_task_with_callbacks
    result = self._execute_task(context, task_copy)
  File "/home/airflow/.local/lib/python3.8/site-packages/airflow/models/taskinstance.py", line 1361, in _execute_task
    result = task_copy.execute(context=context)
  File "/home/airflow/.local/lib/python3.8/site-packages/airflow/operators/python.py", line 150, in execute
    return_value = self.execute_callable()
  File "/home/airflow/.local/lib/python3.8/site-packages/airflow/operators/python.py", line 161, in execute_callable
    return self.python_callable(*self.op_args, **self.op_kwargs)
  File "/opt/airflow/dags/data_injestion_dag/bazefield_kpi_calculation.py", line 271, in fetch_active_power_kpi
    raise ValueError(f"Error fetching data from API: {e}")
ValueError: Error fetching data from API: HTTPSConnectionPool(host='idcc.jsw.in', port=443): Max retries exceeded with url: /Bazefield.Services/api/objects/timeseries/aggregated?objectIds=11002CC087CEB000,11003170EE0EB000,11003170FD4EB000,110031710ACEB000,110031717B8EB000,11003171B24EB000,11003171C00EB000,11003171DD8EB000,11003171EB8EB000,110031733E0EB000,110031734C4EB000,110031735B4EB000,11003176A54EB000,11003177284EB000,1100317739CEB000,110031720D0EB000,11003173790EB000,11003173A68EB000,110031758CCEB000,11003176424EB000,11003176520EB000,11003176620EB000,11003176834EB000,11003173004EB000,110031730FCEB000,11003175A08EB000,11003175C24EB000,11003175D24EB000,11003175E94EB000,11003175FB4EB000,11003176324EB000,110031775B8EB000,11003171260EB000,11003171344EB000,11003171438EB000,11003171520EB000,11003171608EB000,110031716F0EB000,1100317188CEB000,11003171960EB000,11003171A48EB000,11003171CF0EB000,11003171FF0EB000,1100317369CEB000,110031723ACEB000,11003172488EB000,1100317257CEB000,11003172664EB000,11003172750EB000,1100317283CEB000,11003172928EB000,11003175B1CEB000,11003176724EB000,11003176938EB000,110031774A8EB000,110031721D0EB000,110031722CCEB000,11003172A20EB000,11003172B08EB000,11003172BFCEB000,11003173894EB000,11003173988EB000,1100317621CEB000,11003176C94EB000,11003176DCCEB000,11003177174EB000,11003172CE4EB000,11003172DD8EB000,11003172F0CEB000,11003173B58EB000,11003173C54EB000,11003173D50EB000,11003174760EB000,11003175698EB000,11003176B68EB000,11003176F14EB000,1100317705CEB000,11003174B6CEB000,11003175278EB000,11003175374EB000,110031755A0EB000,11003173F2CEB000,11003174C68EB000,11003174D68EB000,11003174F64EB000,11003175060EB000,11003175178EB000,11003175480EB000,110031760C4EB000,11003173E34EB000,11003174030EB000,11003174660EB000,1100317487CEB000,11003174978EB000,11003174A7CEB000,110031731F0EB000,110031732F0EB000,1100317411CEB000,11003174214EB000,11003174324EB000,1100317443CEB000,11003174544EB000,11003174E6CEB000,110031757B4EB000&points=ActivePower&aggregates=TIMEAVERAGE&from=2024-11-22T04:00:00Z&to=2024-11-22T04:59:59Z&interval=10m&format=json (Caused by NewConnectionError('<urllib3.connection.HTTPSConnection object at 0x7fd7c44aeb80>: Failed to establish a new connection: [Errno 111] Connection refused'))
[2024-11-22 05:59:23,065] {taskinstance.py:1544} INFO - Marking task as FAILED. dag_id=kpi_calculation_pipeline, task_id=fetch_data, execution_date=20241122T055244, start_date=20241122T055857, end_date=20241122T055923
[2024-11-22 05:59:23,156] {local_task_job.py:151} INFO - Task exited with return code 1
