[2024-11-21 10:33:54,708] {taskinstance.py:896} INFO - Dependencies all met for <TaskInstance: kpi_calculation_pipeline.fetch_data 2024-11-21T10:32:16.755656+00:00 [queued]>
[2024-11-21 10:33:54,822] {taskinstance.py:896} INFO - Dependencies all met for <TaskInstance: kpi_calculation_pipeline.fetch_data 2024-11-21T10:32:16.755656+00:00 [queued]>
[2024-11-21 10:33:54,823] {taskinstance.py:1087} INFO - 
--------------------------------------------------------------------------------
[2024-11-21 10:33:54,830] {taskinstance.py:1088} INFO - Starting attempt 2 of 2
[2024-11-21 10:33:54,849] {taskinstance.py:1089} INFO - 
--------------------------------------------------------------------------------
[2024-11-21 10:33:55,134] {taskinstance.py:1107} INFO - Executing <Task(PythonOperator): fetch_data> on 2024-11-21T10:32:16.755656+00:00
[2024-11-21 10:33:55,138] {standard_task_runner.py:52} INFO - Started process 716 to run task
[2024-11-21 10:33:55,141] {standard_task_runner.py:76} INFO - Running: ['airflow', 'tasks', 'run', 'kpi_calculation_pipeline', 'fetch_data', '2024-11-21T10:32:16.755656+00:00', '--job-id', '36', '--pool', 'default_pool', '--raw', '--subdir', 'DAGS_FOLDER/data_injestion_dag/bazefield_kpi_calculation.py', '--cfg-path', '/tmp/tmplziou8q2', '--error-file', '/tmp/tmpzcnxdoyt']
[2024-11-21 10:33:55,142] {standard_task_runner.py:77} INFO - Job 36: Subtask fetch_data
[2024-11-21 10:33:55,650] {logging_mixin.py:104} INFO - Running <TaskInstance: kpi_calculation_pipeline.fetch_data 2024-11-21T10:32:16.755656+00:00 [running]> on host bf5936288309
[2024-11-21 10:33:56,125] {taskinstance.py:1300} INFO - Exporting the following env vars:
AIRFLOW_CTX_DAG_OWNER=airflow
AIRFLOW_CTX_DAG_ID=kpi_calculation_pipeline
AIRFLOW_CTX_TASK_ID=fetch_data
AIRFLOW_CTX_EXECUTION_DATE=2024-11-21T10:32:16.755656+00:00
AIRFLOW_CTX_DAG_RUN_ID=manual__2024-11-21T10:32:16.755656+00:00
[2024-11-21 10:33:56,155] {connection.py:362} ERROR - Failed parsing the json for conn_id bazefield_api
Traceback (most recent call last):
  File "/home/airflow/.local/lib/python3.8/site-packages/airflow/models/connection.py", line 359, in extra_dejson
    obj = json.loads(self.extra)
  File "/usr/local/lib/python3.8/json/__init__.py", line 357, in loads
    return _default_decoder.decode(s)
  File "/usr/local/lib/python3.8/json/decoder.py", line 337, in decode
    obj, end = self.raw_decode(s, idx=_w(s, 0).end())
  File "/usr/local/lib/python3.8/json/decoder.py", line 355, in raw_decode
    raise JSONDecodeError("Expecting value", s, err.value) from None
json.decoder.JSONDecodeError: Expecting value: line 2 column 17 (char 78)
[2024-11-21 10:33:56,157] {base.py:69} INFO - Using connection to: id: bazefield_api. Host: https://idcc.jsw.in, Port: None, Schema: , Login: , Password: None, extra: {}
[2024-11-21 10:33:56,157] {connection.py:362} ERROR - Failed parsing the json for conn_id bazefield_api
Traceback (most recent call last):
  File "/home/airflow/.local/lib/python3.8/site-packages/airflow/models/connection.py", line 359, in extra_dejson
    obj = json.loads(self.extra)
  File "/usr/local/lib/python3.8/json/__init__.py", line 357, in loads
    return _default_decoder.decode(s)
  File "/usr/local/lib/python3.8/json/decoder.py", line 337, in decode
    obj, end = self.raw_decode(s, idx=_w(s, 0).end())
  File "/usr/local/lib/python3.8/json/decoder.py", line 355, in raw_decode
    raise JSONDecodeError("Expecting value", s, err.value) from None
json.decoder.JSONDecodeError: Expecting value: line 2 column 17 (char 78)
[2024-11-21 10:33:56,203] {connection.py:362} ERROR - Failed parsing the json for conn_id bazefield_api
Traceback (most recent call last):
  File "/home/airflow/.local/lib/python3.8/site-packages/airflow/models/connection.py", line 359, in extra_dejson
    obj = json.loads(self.extra)
  File "/usr/local/lib/python3.8/json/__init__.py", line 357, in loads
    return _default_decoder.decode(s)
  File "/usr/local/lib/python3.8/json/decoder.py", line 337, in decode
    obj, end = self.raw_decode(s, idx=_w(s, 0).end())
  File "/usr/local/lib/python3.8/json/decoder.py", line 355, in raw_decode
    raise JSONDecodeError("Expecting value", s, err.value) from None
json.decoder.JSONDecodeError: Expecting value: line 2 column 17 (char 78)
[2024-11-21 10:33:56,205] {base.py:69} INFO - Using connection to: id: bazefield_api. Host: https://idcc.jsw.in, Port: None, Schema: , Login: , Password: None, extra: {}
[2024-11-21 10:33:56,206] {connection.py:362} ERROR - Failed parsing the json for conn_id bazefield_api
Traceback (most recent call last):
  File "/home/airflow/.local/lib/python3.8/site-packages/airflow/models/connection.py", line 359, in extra_dejson
    obj = json.loads(self.extra)
  File "/usr/local/lib/python3.8/json/__init__.py", line 357, in loads
    return _default_decoder.decode(s)
  File "/usr/local/lib/python3.8/json/decoder.py", line 337, in decode
    obj, end = self.raw_decode(s, idx=_w(s, 0).end())
  File "/usr/local/lib/python3.8/json/decoder.py", line 355, in raw_decode
    raise JSONDecodeError("Expecting value", s, err.value) from None
json.decoder.JSONDecodeError: Expecting value: line 2 column 17 (char 78)
[2024-11-21 10:33:56,207] {http.py:140} INFO - Sending 'GET' to url: https://idcc.jsw.in/Bazefield.Services/api/objects/timeseries/aggregated?objectIds=&points=ActivePower&aggregates=TIMEAVERAGE&from=2024-11-21T09:00:00Z&to=2024-11-21T09:59:59Z&interval=10m&format=json
[2024-11-21 10:33:57,380] {http.py:154} ERROR - HTTP error: Unauthorized
[2024-11-21 10:33:57,381] {http.py:155} ERROR - "401"
[2024-11-21 10:33:57,382] {taskinstance.py:1501} ERROR - Task failed with exception
Traceback (most recent call last):
  File "/home/airflow/.local/lib/python3.8/site-packages/airflow/providers/http/hooks/http.py", line 152, in check_response
    response.raise_for_status()
  File "/home/airflow/.local/lib/python3.8/site-packages/requests/models.py", line 943, in raise_for_status
    raise HTTPError(http_error_msg, response=self)
requests.exceptions.HTTPError: 401 Client Error: Unauthorized for url: https://idcc.jsw.in/Bazefield.Services/api/objects/timeseries/aggregated?objectIds=&points=ActivePower&aggregates=TIMEAVERAGE&from=2024-11-21T09:00:00Z&to=2024-11-21T09:59:59Z&interval=10m&format=json

During handling of the above exception, another exception occurred:

Traceback (most recent call last):
  File "/opt/airflow/dags/data_injestion_dag/bazefield_kpi_calculation.py", line 55, in fetch_active_power_kpi
    response = http_hook.run(endpoint=full_endpoint)
  File "/home/airflow/.local/lib/python3.8/site-packages/airflow/providers/http/hooks/http.py", line 141, in run
    return self.run_and_check(session, prepped_request, extra_options)
  File "/home/airflow/.local/lib/python3.8/site-packages/airflow/providers/http/hooks/http.py", line 198, in run_and_check
    self.check_response(response)
  File "/home/airflow/.local/lib/python3.8/site-packages/airflow/providers/http/hooks/http.py", line 156, in check_response
    raise AirflowException(str(response.status_code) + ":" + response.reason)
airflow.exceptions.AirflowException: 401:Unauthorized

During handling of the above exception, another exception occurred:

Traceback (most recent call last):
  File "/home/airflow/.local/lib/python3.8/site-packages/airflow/models/taskinstance.py", line 1157, in _run_raw_task
    self._prepare_and_execute_task_with_callbacks(context, task)
  File "/home/airflow/.local/lib/python3.8/site-packages/airflow/models/taskinstance.py", line 1331, in _prepare_and_execute_task_with_callbacks
    result = self._execute_task(context, task_copy)
  File "/home/airflow/.local/lib/python3.8/site-packages/airflow/models/taskinstance.py", line 1361, in _execute_task
    result = task_copy.execute(context=context)
  File "/home/airflow/.local/lib/python3.8/site-packages/airflow/operators/python.py", line 150, in execute
    return_value = self.execute_callable()
  File "/home/airflow/.local/lib/python3.8/site-packages/airflow/operators/python.py", line 161, in execute_callable
    return self.python_callable(*self.op_args, **self.op_kwargs)
  File "/opt/airflow/dags/data_injestion_dag/bazefield_kpi_calculation.py", line 61, in fetch_active_power_kpi
    raise ValueError(f"Error fetching data from API: {e}")
ValueError: Error fetching data from API: 401:Unauthorized
[2024-11-21 10:33:57,391] {taskinstance.py:1544} INFO - Marking task as FAILED. dag_id=kpi_calculation_pipeline, task_id=fetch_data, execution_date=20241121T103216, start_date=20241121T103354, end_date=20241121T103357
[2024-11-21 10:33:57,910] {local_task_job.py:151} INFO - Task exited with return code 1
