[2024-11-22 05:39:19,942] {taskinstance.py:896} INFO - Dependencies all met for <TaskInstance: kpi_calculation_pipeline.store_kpi 2024-11-22T05:37:59.234570+00:00 [queued]>
[2024-11-22 05:39:20,036] {taskinstance.py:896} INFO - Dependencies all met for <TaskInstance: kpi_calculation_pipeline.store_kpi 2024-11-22T05:37:59.234570+00:00 [queued]>
[2024-11-22 05:39:20,043] {taskinstance.py:1087} INFO - 
--------------------------------------------------------------------------------
[2024-11-22 05:39:20,046] {taskinstance.py:1088} INFO - Starting attempt 2 of 2
[2024-11-22 05:39:20,054] {taskinstance.py:1089} INFO - 
--------------------------------------------------------------------------------
[2024-11-22 05:39:20,196] {taskinstance.py:1107} INFO - Executing <Task(PythonOperator): store_kpi> on 2024-11-22T05:37:59.234570+00:00
[2024-11-22 05:39:20,206] {standard_task_runner.py:52} INFO - Started process 1932 to run task
[2024-11-22 05:39:20,213] {standard_task_runner.py:76} INFO - Running: ['airflow', 'tasks', 'run', 'kpi_calculation_pipeline', 'store_kpi', '2024-11-22T05:37:59.234570+00:00', '--job-id', '282', '--pool', 'default_pool', '--raw', '--subdir', 'DAGS_FOLDER/data_injestion_dag/bazefield_kpi_calculation.py', '--cfg-path', '/tmp/tmp8upavfq1', '--error-file', '/tmp/tmp848_h98p']
[2024-11-22 05:39:20,220] {standard_task_runner.py:77} INFO - Job 282: Subtask store_kpi
[2024-11-22 05:39:20,564] {logging_mixin.py:104} INFO - Running <TaskInstance: kpi_calculation_pipeline.store_kpi 2024-11-22T05:37:59.234570+00:00 [running]> on host 1b505405454d
[2024-11-22 05:39:20,971] {taskinstance.py:1300} INFO - Exporting the following env vars:
AIRFLOW_CTX_DAG_OWNER=airflow
AIRFLOW_CTX_DAG_ID=kpi_calculation_pipeline
AIRFLOW_CTX_TASK_ID=store_kpi
AIRFLOW_CTX_EXECUTION_DATE=2024-11-22T05:37:59.234570+00:00
AIRFLOW_CTX_DAG_RUN_ID=manual__2024-11-22T05:37:59.234570+00:00
[2024-11-22 05:39:21,089] {base.py:69} INFO - Using connection to: id: kpi_conn. Host: localhost, Port: 5432, Schema: kpi_storage, Login: postgres, Password: ***, extra: {}
[2024-11-22 05:39:21,095] {taskinstance.py:1501} ERROR - Task failed with exception
Traceback (most recent call last):
  File "/home/airflow/.local/lib/python3.8/site-packages/airflow/models/taskinstance.py", line 1157, in _run_raw_task
    self._prepare_and_execute_task_with_callbacks(context, task)
  File "/home/airflow/.local/lib/python3.8/site-packages/airflow/models/taskinstance.py", line 1331, in _prepare_and_execute_task_with_callbacks
    result = self._execute_task(context, task_copy)
  File "/home/airflow/.local/lib/python3.8/site-packages/airflow/models/taskinstance.py", line 1361, in _execute_task
    result = task_copy.execute(context=context)
  File "/home/airflow/.local/lib/python3.8/site-packages/airflow/operators/python.py", line 150, in execute
    return_value = self.execute_callable()
  File "/home/airflow/.local/lib/python3.8/site-packages/airflow/operators/python.py", line 161, in execute_callable
    return self.python_callable(*self.op_args, **self.op_kwargs)
  File "/opt/airflow/dags/data_injestion_dag/bazefield_kpi_calculation.py", line 326, in store_kpi_in_postgres
    connection = postgres_hook.get_conn()
  File "/home/airflow/.local/lib/python3.8/site-packages/airflow/providers/postgres/hooks/postgres.py", line 115, in get_conn
    self.conn = psycopg2.connect(**conn_args)
  File "/home/airflow/.local/lib/python3.8/site-packages/psycopg2/__init__.py", line 122, in connect
    conn = _connect(dsn, connection_factory=connection_factory, **kwasync)
psycopg2.OperationalError: could not connect to server: Connection refused
	Is the server running on host "localhost" (::1) and accepting
	TCP/IP connections on port 5432?
could not connect to server: Connection refused
	Is the server running on host "localhost" (127.0.0.1) and accepting
	TCP/IP connections on port 5432?

[2024-11-22 05:39:21,111] {taskinstance.py:1544} INFO - Marking task as FAILED. dag_id=kpi_calculation_pipeline, task_id=store_kpi, execution_date=20241122T053759, start_date=20241122T053919, end_date=20241122T053921
[2024-11-22 05:39:21,464] {local_task_job.py:151} INFO - Task exited with return code 1
