[2024-11-21 10:37:40,430] {taskinstance.py:896} INFO - Dependencies all met for <TaskInstance: kpi_calculation_pipeline.fetch_data 2024-11-21T10:35:38.026303+00:00 [queued]>
[2024-11-21 10:37:40,648] {taskinstance.py:896} INFO - Dependencies all met for <TaskInstance: kpi_calculation_pipeline.fetch_data 2024-11-21T10:35:38.026303+00:00 [queued]>
[2024-11-21 10:37:40,649] {taskinstance.py:1087} INFO - 
--------------------------------------------------------------------------------
[2024-11-21 10:37:40,650] {taskinstance.py:1088} INFO - Starting attempt 2 of 2
[2024-11-21 10:37:40,651] {taskinstance.py:1089} INFO - 
--------------------------------------------------------------------------------
[2024-11-21 10:37:41,059] {taskinstance.py:1107} INFO - Executing <Task(PythonOperator): fetch_data> on 2024-11-21T10:35:38.026303+00:00
[2024-11-21 10:37:41,089] {standard_task_runner.py:52} INFO - Started process 778 to run task
[2024-11-21 10:37:41,094] {standard_task_runner.py:76} INFO - Running: ['airflow', 'tasks', 'run', 'kpi_calculation_pipeline', 'fetch_data', '2024-11-21T10:35:38.026303+00:00', '--job-id', '41', '--pool', 'default_pool', '--raw', '--subdir', 'DAGS_FOLDER/data_injestion_dag/bazefield_kpi_calculation.py', '--cfg-path', '/tmp/tmp0r5w1iws', '--error-file', '/tmp/tmpf1iu2zjw']
[2024-11-21 10:37:41,118] {standard_task_runner.py:77} INFO - Job 41: Subtask fetch_data
[2024-11-21 10:37:41,840] {logging_mixin.py:104} INFO - Running <TaskInstance: kpi_calculation_pipeline.fetch_data 2024-11-21T10:35:38.026303+00:00 [running]> on host bf5936288309
[2024-11-21 10:37:42,369] {taskinstance.py:1300} INFO - Exporting the following env vars:
AIRFLOW_CTX_DAG_OWNER=airflow
AIRFLOW_CTX_DAG_ID=kpi_calculation_pipeline
AIRFLOW_CTX_TASK_ID=fetch_data
AIRFLOW_CTX_EXECUTION_DATE=2024-11-21T10:35:38.026303+00:00
AIRFLOW_CTX_DAG_RUN_ID=manual__2024-11-21T10:35:38.026303+00:00
[2024-11-21 10:37:42,454] {connection.py:362} ERROR - Failed parsing the json for conn_id bazefield_api
Traceback (most recent call last):
  File "/home/airflow/.local/lib/python3.8/site-packages/airflow/models/connection.py", line 359, in extra_dejson
    obj = json.loads(self.extra)
  File "/usr/local/lib/python3.8/json/__init__.py", line 357, in loads
    return _default_decoder.decode(s)
  File "/usr/local/lib/python3.8/json/decoder.py", line 337, in decode
    obj, end = self.raw_decode(s, idx=_w(s, 0).end())
  File "/usr/local/lib/python3.8/json/decoder.py", line 355, in raw_decode
    raise JSONDecodeError("Expecting value", s, err.value) from None
json.decoder.JSONDecodeError: Expecting value: line 2 column 17 (char 78)
[2024-11-21 10:37:42,461] {base.py:69} INFO - Using connection to: id: bazefield_api. Host: https://idcc.jsw.in, Port: None, Schema: , Login: , Password: None, extra: {}
[2024-11-21 10:37:42,482] {connection.py:362} ERROR - Failed parsing the json for conn_id bazefield_api
Traceback (most recent call last):
  File "/home/airflow/.local/lib/python3.8/site-packages/airflow/models/connection.py", line 359, in extra_dejson
    obj = json.loads(self.extra)
  File "/usr/local/lib/python3.8/json/__init__.py", line 357, in loads
    return _default_decoder.decode(s)
  File "/usr/local/lib/python3.8/json/decoder.py", line 337, in decode
    obj, end = self.raw_decode(s, idx=_w(s, 0).end())
  File "/usr/local/lib/python3.8/json/decoder.py", line 355, in raw_decode
    raise JSONDecodeError("Expecting value", s, err.value) from None
json.decoder.JSONDecodeError: Expecting value: line 2 column 17 (char 78)
[2024-11-21 10:37:42,484] {http.py:140} INFO - Sending 'GET' to url: https://idcc.jsw.in/Bazefield.Services/api/objects/timeseries/aggregated?objectIds=11002CC087CEB000,11003170EE0EB000,11003170FD4EB000,110031710ACEB000,110031717B8EB000,11003171B24EB000,11003171C00EB000,11003171DD8EB000,11003171EB8EB000,110031733E0EB000,110031734C4EB000,110031735B4EB000,11003176A54EB000,11003177284EB000,1100317739CEB000,110031720D0EB000,11003173790EB000,11003173A68EB000,110031758CCEB000,11003176424EB000,11003176520EB000,11003176620EB000,11003176834EB000,11003173004EB000,110031730FCEB000,11003175A08EB000,11003175C24EB000,11003175D24EB000,11003175E94EB000,11003175FB4EB000,11003176324EB000,110031775B8EB000,11003171260EB000,11003171344EB000,11003171438EB000,11003171520EB000,11003171608EB000,110031716F0EB000,1100317188CEB000,11003171960EB000,11003171A48EB000,11003171CF0EB000,11003171FF0EB000,1100317369CEB000,110031723ACEB000,11003172488EB000,1100317257CEB000,11003172664EB000,11003172750EB000,1100317283CEB000,11003172928EB000,11003175B1CEB000,11003176724EB000,11003176938EB000,110031774A8EB000,110031721D0EB000,110031722CCEB000,11003172A20EB000,11003172B08EB000,11003172BFCEB000,11003173894EB000,11003173988EB000,1100317621CEB000,11003176C94EB000,11003176DCCEB000,11003177174EB000,11003172CE4EB000,11003172DD8EB000,11003172F0CEB000,11003173B58EB000,11003173C54EB000,11003173D50EB000,11003174760EB000,11003175698EB000,11003176B68EB000,11003176F14EB000,1100317705CEB000,11003174B6CEB000,11003175278EB000,11003175374EB000,110031755A0EB000,11003173F2CEB000,11003174C68EB000,11003174D68EB000,11003174F64EB000,11003175060EB000,11003175178EB000,11003175480EB000,110031760C4EB000,11003173E34EB000,11003174030EB000,11003174660EB000,1100317487CEB000,11003174978EB000,11003174A7CEB000,110031731F0EB000,110031732F0EB000,1100317411CEB000,11003174214EB000,11003174324EB000,1100317443CEB000,11003174544EB000,11003174E6CEB000,110031757B4EB000&points=ActivePower&aggregates=TIMEAVERAGE&from=2024-11-21T09:00:00Z&to=2024-11-21T09:59:59Z&interval=10m&format=json
[2024-11-21 10:37:43,837] {http.py:154} ERROR - HTTP error: Unauthorized
[2024-11-21 10:37:43,838] {http.py:155} ERROR - "401"
[2024-11-21 10:37:43,862] {taskinstance.py:1501} ERROR - Task failed with exception
Traceback (most recent call last):
  File "/home/airflow/.local/lib/python3.8/site-packages/airflow/providers/http/hooks/http.py", line 152, in check_response
    response.raise_for_status()
  File "/home/airflow/.local/lib/python3.8/site-packages/requests/models.py", line 943, in raise_for_status
    raise HTTPError(http_error_msg, response=self)
requests.exceptions.HTTPError: 401 Client Error: Unauthorized for url: https://idcc.jsw.in/Bazefield.Services/api/objects/timeseries/aggregated?objectIds=11002CC087CEB000,11003170EE0EB000,11003170FD4EB000,110031710ACEB000,110031717B8EB000,11003171B24EB000,11003171C00EB000,11003171DD8EB000,11003171EB8EB000,110031733E0EB000,110031734C4EB000,110031735B4EB000,11003176A54EB000,11003177284EB000,1100317739CEB000,110031720D0EB000,11003173790EB000,11003173A68EB000,110031758CCEB000,11003176424EB000,11003176520EB000,11003176620EB000,11003176834EB000,11003173004EB000,110031730FCEB000,11003175A08EB000,11003175C24EB000,11003175D24EB000,11003175E94EB000,11003175FB4EB000,11003176324EB000,110031775B8EB000,11003171260EB000,11003171344EB000,11003171438EB000,11003171520EB000,11003171608EB000,110031716F0EB000,1100317188CEB000,11003171960EB000,11003171A48EB000,11003171CF0EB000,11003171FF0EB000,1100317369CEB000,110031723ACEB000,11003172488EB000,1100317257CEB000,11003172664EB000,11003172750EB000,1100317283CEB000,11003172928EB000,11003175B1CEB000,11003176724EB000,11003176938EB000,110031774A8EB000,110031721D0EB000,110031722CCEB000,11003172A20EB000,11003172B08EB000,11003172BFCEB000,11003173894EB000,11003173988EB000,1100317621CEB000,11003176C94EB000,11003176DCCEB000,11003177174EB000,11003172CE4EB000,11003172DD8EB000,11003172F0CEB000,11003173B58EB000,11003173C54EB000,11003173D50EB000,11003174760EB000,11003175698EB000,11003176B68EB000,11003176F14EB000,1100317705CEB000,11003174B6CEB000,11003175278EB000,11003175374EB000,110031755A0EB000,11003173F2CEB000,11003174C68EB000,11003174D68EB000,11003174F64EB000,11003175060EB000,11003175178EB000,11003175480EB000,110031760C4EB000,11003173E34EB000,11003174030EB000,11003174660EB000,1100317487CEB000,11003174978EB000,11003174A7CEB000,110031731F0EB000,110031732F0EB000,1100317411CEB000,11003174214EB000,11003174324EB000,1100317443CEB000,11003174544EB000,11003174E6CEB000,110031757B4EB000&points=ActivePower&aggregates=TIMEAVERAGE&from=2024-11-21T09:00:00Z&to=2024-11-21T09:59:59Z&interval=10m&format=json

During handling of the above exception, another exception occurred:

Traceback (most recent call last):
  File "/opt/airflow/dags/data_injestion_dag/bazefield_kpi_calculation.py", line 156, in fetch_active_power_kpi
    response = http_hook.run(endpoint=full_endpoint)
  File "/home/airflow/.local/lib/python3.8/site-packages/airflow/providers/http/hooks/http.py", line 141, in run
    return self.run_and_check(session, prepped_request, extra_options)
  File "/home/airflow/.local/lib/python3.8/site-packages/airflow/providers/http/hooks/http.py", line 198, in run_and_check
    self.check_response(response)
  File "/home/airflow/.local/lib/python3.8/site-packages/airflow/providers/http/hooks/http.py", line 156, in check_response
    raise AirflowException(str(response.status_code) + ":" + response.reason)
airflow.exceptions.AirflowException: 401:Unauthorized

During handling of the above exception, another exception occurred:

Traceback (most recent call last):
  File "/home/airflow/.local/lib/python3.8/site-packages/airflow/models/taskinstance.py", line 1157, in _run_raw_task
    self._prepare_and_execute_task_with_callbacks(context, task)
  File "/home/airflow/.local/lib/python3.8/site-packages/airflow/models/taskinstance.py", line 1331, in _prepare_and_execute_task_with_callbacks
    result = self._execute_task(context, task_copy)
  File "/home/airflow/.local/lib/python3.8/site-packages/airflow/models/taskinstance.py", line 1361, in _execute_task
    result = task_copy.execute(context=context)
  File "/home/airflow/.local/lib/python3.8/site-packages/airflow/operators/python.py", line 150, in execute
    return_value = self.execute_callable()
  File "/home/airflow/.local/lib/python3.8/site-packages/airflow/operators/python.py", line 161, in execute_callable
    return self.python_callable(*self.op_args, **self.op_kwargs)
  File "/opt/airflow/dags/data_injestion_dag/bazefield_kpi_calculation.py", line 162, in fetch_active_power_kpi
    raise ValueError(f"Error fetching data from API: {e}")
ValueError: Error fetching data from API: 401:Unauthorized
[2024-11-21 10:37:43,874] {taskinstance.py:1544} INFO - Marking task as FAILED. dag_id=kpi_calculation_pipeline, task_id=fetch_data, execution_date=20241121T103538, start_date=20241121T103740, end_date=20241121T103743
[2024-11-21 10:37:44,428] {local_task_job.py:151} INFO - Task exited with return code 1
