[2024-11-21 11:42:21,868] {taskinstance.py:896} INFO - Dependencies all met for <TaskInstance: kpi_calculation_pipeline.fetch_data 2024-11-21T11:37:13.983902+00:00 [queued]>
[2024-11-21 11:42:22,230] {taskinstance.py:896} INFO - Dependencies all met for <TaskInstance: kpi_calculation_pipeline.fetch_data 2024-11-21T11:37:13.983902+00:00 [queued]>
[2024-11-21 11:42:22,252] {taskinstance.py:1087} INFO - 
--------------------------------------------------------------------------------
[2024-11-21 11:42:22,254] {taskinstance.py:1088} INFO - Starting attempt 1 of 2
[2024-11-21 11:42:22,260] {taskinstance.py:1089} INFO - 
--------------------------------------------------------------------------------
[2024-11-21 11:42:22,929] {taskinstance.py:1107} INFO - Executing <Task(PythonOperator): fetch_data> on 2024-11-21T11:37:13.983902+00:00
[2024-11-21 11:42:22,937] {standard_task_runner.py:52} INFO - Started process 1789 to run task
[2024-11-21 11:42:22,945] {standard_task_runner.py:76} INFO - Running: ['airflow', 'tasks', 'run', 'kpi_calculation_pipeline', 'fetch_data', '2024-11-21T11:37:13.983902+00:00', '--job-id', '89', '--pool', 'default_pool', '--raw', '--subdir', 'DAGS_FOLDER/data_injestion_dag/bazefield_kpi_calculation.py', '--cfg-path', '/tmp/tmpq9_hebia', '--error-file', '/tmp/tmp2nc6lxw_']
[2024-11-21 11:42:22,947] {standard_task_runner.py:77} INFO - Job 89: Subtask fetch_data
[2024-11-21 11:42:23,607] {logging_mixin.py:104} INFO - Running <TaskInstance: kpi_calculation_pipeline.fetch_data 2024-11-21T11:37:13.983902+00:00 [running]> on host 1b505405454d
[2024-11-21 11:42:25,182] {taskinstance.py:1300} INFO - Exporting the following env vars:
AIRFLOW_CTX_DAG_OWNER=airflow
AIRFLOW_CTX_DAG_ID=kpi_calculation_pipeline
AIRFLOW_CTX_TASK_ID=fetch_data
AIRFLOW_CTX_EXECUTION_DATE=2024-11-21T11:37:13.983902+00:00
AIRFLOW_CTX_DAG_RUN_ID=scheduled__2024-11-21T11:37:13.983902+00:00
[2024-11-21 11:42:25,367] {base.py:69} INFO - Using connection to: id: bazefield_api. Host: https://idcc.jsw.in, Port: None, Schema: , Login: , Password: None, extra: {'Authorization': '***'}
[2024-11-21 11:42:25,400] {http.py:140} INFO - Sending 'GET' to url: https://idcc.jsw.in/Bazefield.Services/api/objects/timeseries/aggregated?objectIds=110031757B4EB000,11003174E6CEB000&points=ActivePower&aggregates=TIMEAVERAGE&from=2024-11-21T10:00:00Z&to=2024-11-21T10:59:59Z&interval=1h&format=json
[2024-11-21 11:42:26,655] {logging_mixin.py:104} INFO - {'objects': {'110031757B4EB000': {'points': {'ActivePower': [{'objectId': '110031757B4EB000', 'pointName': 'ActivePower', 'aggregate': 'TIMEAVERAGE', 'timeSeries': [{'t': 1732183200000, 'q': 524480, 'v': 572.4578056911884, 't_local': '2024-11-21T15:30:00.0000000+05:30'}], 'valueType': 'System.Double', 'from': '2024-11-21T10:00:00.0000000Z', 'to': '2024-11-21T10:59:59.0000000Z', 'interval': '1h', 'resultId': 0, 'isHdaCompatible': True}]}}, '11003174E6CEB000': {'points': {'ActivePower': [{'objectId': '11003174E6CEB000', 'pointName': 'ActivePower', 'aggregate': 'TIMEAVERAGE', 'timeSeries': [{'t': 1732183200000, 'q': 524480, 'v': 646.0206278834871, 't_local': '2024-11-21T15:30:00.0000000+05:30'}], 'valueType': 'System.Double', 'from': '2024-11-21T10:00:00.0000000Z', 'to': '2024-11-21T10:59:59.0000000Z', 'interval': '1h', 'resultId': 0, 'isHdaCompatible': True}]}}}, 'replyInfo': {'rcvTime': 1732189346668, 'replyTime': 1732189346674}}
[2024-11-21 11:42:26,731] {taskinstance.py:1501} ERROR - Task failed with exception
Traceback (most recent call last):
  File "/home/airflow/.local/lib/python3.8/site-packages/pandas/core/indexes/base.py", line 3081, in get_loc
    return self._engine.get_loc(casted_key)
  File "pandas/_libs/index.pyx", line 70, in pandas._libs.index.IndexEngine.get_loc
  File "pandas/_libs/index.pyx", line 101, in pandas._libs.index.IndexEngine.get_loc
  File "pandas/_libs/hashtable_class_helper.pxi", line 4554, in pandas._libs.hashtable.PyObjectHashTable.get_item
  File "pandas/_libs/hashtable_class_helper.pxi", line 4562, in pandas._libs.hashtable.PyObjectHashTable.get_item
KeyError: 'Timestamp'

The above exception was the direct cause of the following exception:

Traceback (most recent call last):
  File "/home/airflow/.local/lib/python3.8/site-packages/airflow/models/taskinstance.py", line 1157, in _run_raw_task
    self._prepare_and_execute_task_with_callbacks(context, task)
  File "/home/airflow/.local/lib/python3.8/site-packages/airflow/models/taskinstance.py", line 1331, in _prepare_and_execute_task_with_callbacks
    result = self._execute_task(context, task_copy)
  File "/home/airflow/.local/lib/python3.8/site-packages/airflow/models/taskinstance.py", line 1361, in _execute_task
    result = task_copy.execute(context=context)
  File "/home/airflow/.local/lib/python3.8/site-packages/airflow/operators/python.py", line 150, in execute
    return_value = self.execute_callable()
  File "/home/airflow/.local/lib/python3.8/site-packages/airflow/operators/python.py", line 161, in execute_callable
    return self.python_callable(*self.op_args, **self.op_kwargs)
  File "/opt/airflow/dags/data_injestion_dag/bazefield_kpi_calculation.py", line 289, in fetch_active_power_kpi
    pivot_df['Timestamp'] = pd.to_datetime(pivot_df['Timestamp'])
  File "/home/airflow/.local/lib/python3.8/site-packages/pandas/core/frame.py", line 3024, in __getitem__
    indexer = self.columns.get_loc(key)
  File "/home/airflow/.local/lib/python3.8/site-packages/pandas/core/indexes/base.py", line 3083, in get_loc
    raise KeyError(key) from err
KeyError: 'Timestamp'
[2024-11-21 11:42:26,793] {taskinstance.py:1544} INFO - Marking task as UP_FOR_RETRY. dag_id=kpi_calculation_pipeline, task_id=fetch_data, execution_date=20241121T113713, start_date=20241121T114221, end_date=20241121T114226
[2024-11-21 11:42:28,010] {local_task_job.py:151} INFO - Task exited with return code 1
