[2024-11-21 10:13:39,962] {taskinstance.py:896} INFO - Dependencies all met for <TaskInstance: kpi_calculation_pipeline.fetch_data 2024-11-21T10:06:57.355706+00:00 [queued]>
[2024-11-21 10:13:40,097] {taskinstance.py:896} INFO - Dependencies all met for <TaskInstance: kpi_calculation_pipeline.fetch_data 2024-11-21T10:06:57.355706+00:00 [queued]>
[2024-11-21 10:13:40,109] {taskinstance.py:1087} INFO - 
--------------------------------------------------------------------------------
[2024-11-21 10:13:40,110] {taskinstance.py:1088} INFO - Starting attempt 2 of 2
[2024-11-21 10:13:40,135] {taskinstance.py:1089} INFO - 
--------------------------------------------------------------------------------
[2024-11-21 10:13:40,510] {taskinstance.py:1107} INFO - Executing <Task(PythonOperator): fetch_data> on 2024-11-21T10:06:57.355706+00:00
[2024-11-21 10:13:40,515] {standard_task_runner.py:52} INFO - Started process 355 to run task
[2024-11-21 10:13:40,518] {standard_task_runner.py:76} INFO - Running: ['airflow', 'tasks', 'run', 'kpi_calculation_pipeline', 'fetch_data', '2024-11-21T10:06:57.355706+00:00', '--job-id', '16', '--pool', 'default_pool', '--raw', '--subdir', 'DAGS_FOLDER/data_injestion_dag/bazefield_kpi_calculation.py', '--cfg-path', '/tmp/tmpm2iplc08', '--error-file', '/tmp/tmpipdlv4js']
[2024-11-21 10:13:40,520] {standard_task_runner.py:77} INFO - Job 16: Subtask fetch_data
[2024-11-21 10:13:40,936] {logging_mixin.py:104} INFO - Running <TaskInstance: kpi_calculation_pipeline.fetch_data 2024-11-21T10:06:57.355706+00:00 [running]> on host bf5936288309
[2024-11-21 10:13:41,386] {taskinstance.py:1300} INFO - Exporting the following env vars:
AIRFLOW_CTX_DAG_OWNER=airflow
AIRFLOW_CTX_DAG_ID=kpi_calculation_pipeline
AIRFLOW_CTX_TASK_ID=fetch_data
AIRFLOW_CTX_EXECUTION_DATE=2024-11-21T10:06:57.355706+00:00
AIRFLOW_CTX_DAG_RUN_ID=scheduled__2024-11-21T10:06:57.355706+00:00
[2024-11-21 10:13:41,422] {base.py:69} INFO - Using connection to: id: bazefield_api. Host: https://idcc.jsw.in, Port: None, Schema: , Login: , Password: None, extra: {'Authorization': '***'}
[2024-11-21 10:13:41,423] {taskinstance.py:1501} ERROR - Task failed with exception
Traceback (most recent call last):
  File "/opt/airflow/dags/data_injestion_dag/bazefield_kpi_calculation.py", line 154, in fetch_active_power_kpi
    response = http_hook.run(endpoint=endpoint, data=None, params=params)
  File "/home/airflow/.local/lib/python3.8/site-packages/airflow/providers/http/hooks/http.py", line 131, in run
    req = requests.Request(self.method, url, params=data, headers=headers, **request_kwargs)
TypeError: type object got multiple values for keyword argument 'params'

During handling of the above exception, another exception occurred:

Traceback (most recent call last):
  File "/home/airflow/.local/lib/python3.8/site-packages/airflow/models/taskinstance.py", line 1157, in _run_raw_task
    self._prepare_and_execute_task_with_callbacks(context, task)
  File "/home/airflow/.local/lib/python3.8/site-packages/airflow/models/taskinstance.py", line 1331, in _prepare_and_execute_task_with_callbacks
    result = self._execute_task(context, task_copy)
  File "/home/airflow/.local/lib/python3.8/site-packages/airflow/models/taskinstance.py", line 1361, in _execute_task
    result = task_copy.execute(context=context)
  File "/home/airflow/.local/lib/python3.8/site-packages/airflow/operators/python.py", line 150, in execute
    return_value = self.execute_callable()
  File "/home/airflow/.local/lib/python3.8/site-packages/airflow/operators/python.py", line 161, in execute_callable
    return self.python_callable(*self.op_args, **self.op_kwargs)
  File "/opt/airflow/dags/data_injestion_dag/bazefield_kpi_calculation.py", line 160, in fetch_active_power_kpi
    raise ValueError(f"Error fetching data from API: {e}")
ValueError: Error fetching data from API: type object got multiple values for keyword argument 'params'
[2024-11-21 10:13:41,460] {taskinstance.py:1544} INFO - Marking task as FAILED. dag_id=kpi_calculation_pipeline, task_id=fetch_data, execution_date=20241121T100657, start_date=20241121T101339, end_date=20241121T101341
[2024-11-21 10:13:41,985] {local_task_job.py:151} INFO - Task exited with return code 1
